<?xml version="1.0" ?>
<!-- =================================================================================== -->
<!-- |    This document was autogenerated by xacro from pioneer3at.urdf.xacro          | -->
<!-- |    EDITING THIS FILE BY HAND IS NOT RECOMMENDED                                 | -->
<!-- =================================================================================== -->
<robot name="pioneer3at" xmlns:controller="http://playerstage.sourceforge.net/gazebo/xmlschema/#controller" xmlns:interface="http://playerstage.sourceforge.net/gazebo/xmlschema/#interface" xmlns:sensor="http://playerstage.sourceforge.net/gazebo/xmlschema/#sensor" xmlns:xacro="http://ros.org/wiki/xacro">
  <!-- Chassis -->
  <link name="base_link">
    <!--  For pointers on inertial and gazebo-related parameters see
		       * http://wiki.ros.org/urdf/Tutorials/Adding%20Physical%20and%20Collision%20Properties%20to%20a%20URDF%20Model
                       * http://answers.gazebosim.org/question/4372/the-inertia-matrix-explained/
		       * http://gazebosim.org/tutorials?tut=inertia&cat=build_robot, and 
                       * http://gazebosim.org/tutorials/?tut=ros_urdf
                       * http://en.wikipedia.org/wiki/List_of_moment_of_inertia_tensors  
                -->
    <inertial>
      <mass value="21.5"/>
      <!-- P3AT 18.6kg plus three batteries @ 2.4kg each  minus four wheels @ 1.4 kg ea and top plate @ 0.1 kg-->
      <origin xyz=" -0.1 0 0.177"/>
      <inertia ixx="0.3338" ixy="0.0" ixz="0.0" iyy="0.4783" iyz="0.0" izz="0.3338"/>
    </inertial>
    <visual>
      <origin rpy="0 0 0" xyz="0 0 0.177"/>
      <geometry name="pioneer_geom">
        <mesh filename="package://amr_robots_description/meshes/p3at_meshes/chassis.stl"/>
      </geometry>
      <material name="ChassisRed">
        <color rgba="0.851 0.0 0.0 1.0"/>
      </material>
    </visual>
    <collision>
      <origin rpy="0 0 0" xyz="0 0 0.177"/>
      <geometry>
        <mesh filename="package://amr_robots_description/meshes/p3at_meshes/chassis.stl"/>
      </geometry>
    </collision>
  </link>
  <gazebo reference="base_link">
    <material value="Gazebo/Red"/>
  </gazebo>
  <!-- Top -->
  <link name="top_plate">
    <inertial>
      <mass value="0.1"/>
      <origin xyz="-0.025 0 -0.223"/>
      <inertia ixx="1.0" ixy="0.0" ixz="0.0" iyy="1.0" iyz="0.0" izz="1.0"/>
    </inertial>
    <visual>
      <origin rpy="0 0 0" xyz="0 0 0"/>
      <geometry name="pioneer_geom">
        <mesh filename="package://amr_robots_description/meshes/p3at_meshes/top.stl"/>
      </geometry>
      <material name="TopBlack">
        <color rgba="0.038 0.038 0.038 1.0"/>
      </material>
    </visual>
  </link>
  <gazebo reference="top_plate">
    <material>Gazebo/Black</material>
  </gazebo>
  <joint name="base_top_joint" type="fixed">
    <origin rpy="0 0 0" xyz="0.003 0 0.274"/>
    <parent link="base_link"/>
    <child link="top_plate"/>
  </joint>
  <!-- Front + Back Sonar -->
 
  <link name="p3at_front_left_axle">
    <inertial>
      <mass value="0.1"/>
      <origin xyz="0 0 0"/>
      <inertia ixx="1.0" ixy="0.0" ixz="0.0" iyy="1.0" iyz="0.0" izz="1.0"/>
    </inertial>
    <visual>
      <origin rpy="0 0 0" xyz="0 0 0"/>
      <geometry name="pioneer_geom">
        <mesh filename="package://amr_robots_description/meshes/p3at_meshes/axle.stl"/>
      </geometry>
      <material name="AxleGrey">
        <color rgba="0.5 0.5 0.5 1"/>
      </material>
    </visual>
  </link>
  <gazebo reference="p3at_front_left_axle">
    <material value="Gazebo/Grey"/>
  </gazebo>
  <joint name="base_front_left_axle_joint" type="fixed">
    <origin rpy="0 0 0" xyz="0.135 0.156 0.111"/>
    <parent link="base_link"/>
    <child link="p3at_front_left_axle"/>
  </joint>
  <link name="p3at_front_left_hub">
    <inertial>
      <mass value="0.1"/>
      <origin xyz="0 0 0"/>
      <inertia ixx="1.0" ixy="0.0" ixz="0.0" iyy="1.0" iyz="0.0" izz="1.0"/>
    </inertial>
    <visual>
      <origin rpy="0 0 0" xyz="0 0 0"/>
      <geometry name="pioneer_geom">
        <mesh filename="package://amr_robots_description/meshes/p3at_meshes/left_hubcap.stl"/>
      </geometry>
      <material name="HubcapYellow">
        <color rgba="1.0 0.811 0.151 1.0"/>
      </material>
    </visual>
  </link>
  <gazebo reference="p3at_front_left_hub">
    <material value="Gazebo/Yellow"/>
  </gazebo>
  <joint name="base_front_left_hub_joint" type="fixed">
    <origin rpy="0 0 0" xyz="0 0.041 0"/>
    <parent link="p3at_front_left_axle"/>
    <child link="p3at_front_left_hub"/>
  </joint>
  <link name="p3at_front_left_wheel">
    <inertial>
      <mass value="1.2"/>
      <!-- 1.4 kg - axle 0.1 kg - hub 0.1 kg -->
      <origin xyz="0 0 0"/>
      <inertia ixx="0.012411765597" ixy="0" ixz="0" iyy="0.015218160428" iyz="0" izz="0.011763977943"/>
    </inertial>
    <visual>
      <origin rpy="0 0 0" xyz="0 0 0"/>
      <geometry name="pioneer_geom">
        <mesh filename="package://amr_robots_description/meshes/p3at_meshes/wheel.stl"/>
      </geometry>
      <material name="WheelBlack">
        <color rgba="0.117 0.117 0.117 1"/>
      </material>
    </visual>
    <collision>
      <origin rpy="-1.57079635 0 0" xyz="0 0 0"/>
      <geometry>
        <!--mesh filename="package://amr_robots_description/meshes/p3at_meshes/wheel.stl"/-->
        <cylinder length="0.075" radius="0.111"/>
      </geometry>
    </collision>
  </link>
  <gazebo reference="p3at_front_left_wheel">
    <material value="Gazebo/Black"/>
  </gazebo>
  <joint name="p3at_front_left_wheel_joint" type="continuous">
    <axis xyz="0 1 0"/>
    <anchor xyz="0 0 0"/>
    <limit effort="100" velocity="100"/>
    <joint_properties damping="0.7"/>
    <origin rpy="0 0 0" xyz="0 0 0"/>
    <parent link="p3at_front_left_hub"/>
    <child link="p3at_front_left_wheel"/>
  </joint>
  <!-- Back Axles + Wheels + Hubcaps -->
  <link name="p3at_back_left_axle">
    <inertial>
      <mass value="0.1"/>
      <origin xyz="0 0 0"/>
      <inertia ixx="1.0" ixy="0.0" ixz="0.0" iyy="1.0" iyz="0.0" izz="1.0"/>
    </inertial>
    <visual>
      <origin rpy="0 0 0" xyz="0 0 0"/>
      <geometry name="pioneer_geom">
        <mesh filename="package://amr_robots_description/meshes/p3at_meshes/axle.stl"/>
      </geometry>
      <material name="AxleGrey">
        <color rgba="0.5 0.5 0.5 1"/>
      </material>
    </visual>
    <collision>
      <origin rpy="0 0 0" xyz="0 0 0"/>
      <geometry>
        <mesh filename="package://amr_robots_description/meshes/p3at_meshes/axle.stl"/>
      </geometry>
    </collision>
  </link>
  <gazebo reference="p3at_back_left_axle">
    <material value="Gazebo/Grey"/>
  </gazebo>
  <joint name="p3at_back_left_axle_joint" type="fixed">
    <origin rpy="0 0 0" xyz="-0.134 0.156 0.111"/>
    <parent link="base_link"/>
    <child link="p3at_back_left_axle"/>
  </joint>
  <link name="p3at_back_left_hub">
    <inertial>
      <mass value="0.1"/>
      <origin xyz="0 0 0"/>
      <inertia ixx="1.0" ixy="0.0" ixz="0.0" iyy="1.0" iyz="0.0" izz="1.0"/>
    </inertial>
    <visual>
      <origin rpy="0 0 0" xyz="0 0 0"/>
      <geometry name="pioneer_geom">
        <mesh filename="package://amr_robots_description/meshes/p3at_meshes/left_hubcap.stl"/>
      </geometry>
      <material name="HubcapYellow"/>
    </visual>
    <collision>
      <origin rpy="0 0 0" xyz="0 0 0"/>
      <geometry>
        <mesh filename="package://amr_robots_description/meshes/p3at_meshes/left_hubcap.stl"/>
      </geometry>
    </collision>
  </link>
  <gazebo reference="p3at_back_left_hub">
    <material value="Gazebo/Yellow"/>
  </gazebo>
  <joint name="p3at_back_left_hub_joint" type="fixed">
    <origin rpy="0 0 0" xyz="-0 0.041 0"/>
    <parent link="p3at_back_left_axle"/>
    <child link="p3at_back_left_hub"/>
  </joint>
  <link name="p3at_back_left_wheel">
    <inertial>
      <mass value="1.2"/>
      <origin xyz="0 0 0"/>
      <inertia ixx="0.012411765597" ixy="0" ixz="0" iyy="0.015218160428" iyz="0" izz="0.011763977943"/>
    </inertial>
    <visual>
      <origin rpy="0 0 0" xyz="0 0 0"/>
      <geometry name="pioneer_geom">
        <mesh filename="package://amr_robots_description/meshes/p3at_meshes/wheel.stl"/>
      </geometry>
      <material name="WheelBlack"/>
    </visual>
    <collision>
      <origin rpy="-1.57079635 0 0" xyz="0 0 0"/>
      <geometry>
        <!--mesh filename="package://amr_robots_description/meshes/p3at_meshes/wheel.stl"/-->
        <cylinder length="0.075" radius="0.111"/>
      </geometry>
    </collision>
  </link>
  <gazebo reference="p3at_back_left_wheel">
    <material value="Gazebo/Black"/>
  </gazebo>
  <joint name="p3at_back_left_wheel_joint" type="continuous">
    <axis xyz="0 1 0"/>
    <anchor xyz="0 0 0"/>
    <limit effort="100" velocity="100"/>
    <joint_properties damping="0.7"/>
    <origin rpy="0 0 0" xyz="0 0 0"/>
    <parent link="p3at_back_left_hub"/>
    <child link="p3at_back_left_wheel"/>
  </joint>
  <!-- see http://gazebosim.org/tutorials/?tut=ros_urdf -->
  <gazebo reference="p3at_back_left_wheel">
    <kp>1000000.0</kp>
    <!-- kp and kd for rubber -->
    <kd>100.0</kd>
    <mu1>1.0</mu1>
    <!-- was 10 -->
    <mu2>1.0</mu2>
    <!-- how to get these into <surface><friction><ode>... ?
        slip1 0.5 /slip1 
         slip2 0 /slip2 
      -->
    <!-- fdir1 0 1 0 /fdir1 -->
    <!-- see http://github.com/MobileRobots/amr-ros-config/issues/6 -->
    <maxVel>1.0</maxVel>
    <minDepth>0.00</minDepth>
    <material value="Gazebo/Black"/>
  </gazebo>
  <gazebo reference="p3at_front_left_wheel">
    <kp>1000000.0</kp>
    <!-- kp and kd for rubber -->
    <kd>100.0</kd>
    <mu1>1.0</mu1>
    <!-- was 10 -->
    <mu2>1.0</mu2>
    <!-- how to get these into <surface><friction><ode>... ?
        slip1 0.5 /slip1 
         slip2 0 /slip2 
      -->
    <!-- fdir1 0 1 0 /fdir1 -->
    <!-- see http://github.com/MobileRobots/amr-ros-config/issues/6 -->
    <maxVel>1.0</maxVel>
    <minDepth>0.00</minDepth>
    <material value="Gazebo/Black"/>
  </gazebo>
  <!-- Front Axles + Wheels + Hubcaps -->
  <link name="p3at_front_right_axle">
    <inertial>
      <mass value="0.1"/>
      <origin xyz="0 0 0"/>
      <inertia ixx="1.0" ixy="0.0" ixz="0.0" iyy="1.0" iyz="0.0" izz="1.0"/>
    </inertial>
    <visual>
      <origin rpy="0 0 0" xyz="0 0 0"/>
      <geometry name="pioneer_geom">
        <mesh filename="package://amr_robots_description/meshes/p3at_meshes/axle.stl"/>
      </geometry>
      <material name="AxleGrey">
        <color rgba="0.5 0.5 0.5 1"/>
      </material>
    </visual>
  </link>
  <gazebo reference="p3at_front_right_axle">
    <material value="Gazebo/Grey"/>
  </gazebo>
  <joint name="base_front_right_axle_joint" type="fixed">
    <origin rpy="0 0 0" xyz="0.135 -0.156 0.111"/>
    <parent link="base_link"/>
    <child link="p3at_front_right_axle"/>
  </joint>
  <link name="p3at_front_right_hub">
    <inertial>
      <mass value="0.1"/>
      <origin xyz="0 0 0"/>
      <inertia ixx="1.0" ixy="0.0" ixz="0.0" iyy="1.0" iyz="0.0" izz="1.0"/>
    </inertial>
    <visual>
      <origin rpy="0 0 0" xyz="0 0 0"/>
      <geometry name="pioneer_geom">
        <mesh filename="package://amr_robots_description/meshes/p3at_meshes/right_hubcap.stl"/>
      </geometry>
      <material name="HubcapYellow">
        <color rgba="1.0 0.811 0.151 1.0"/>
      </material>
    </visual>
  </link>
  <gazebo reference="p3at_front_right_hub">
    <material value="Gazebo/Yellow"/>
  </gazebo>
  <joint name="base_front_right_hub_joint" type="fixed">
    <origin rpy="0 0 0" xyz="0 -0.041 0"/>
    <parent link="p3at_front_right_axle"/>
    <child link="p3at_front_right_hub"/>
  </joint>
  <link name="p3at_front_right_wheel">
    <inertial>
      <mass value="1.2"/>
      <!-- 1.4 kg - axle 0.1 kg - hub 0.1 kg -->
      <origin xyz="0 0 0"/>
      <inertia ixx="0.012411765597" ixy="0" ixz="0" iyy="0.015218160428" iyz="0" izz="0.011763977943"/>
    </inertial>
    <visual>
      <origin rpy="0 0 0" xyz="0 0 0"/>
      <geometry name="pioneer_geom">
        <mesh filename="package://amr_robots_description/meshes/p3at_meshes/wheel.stl"/>
      </geometry>
      <material name="WheelBlack">
        <color rgba="0.117 0.117 0.117 1"/>
      </material>
    </visual>
    <collision>
      <origin rpy="-1.57079635 0 0" xyz="0 0 0"/>
      <geometry>
        <!--mesh filename="package://amr_robots_description/meshes/p3at_meshes/wheel.stl"/-->
        <cylinder length="0.075" radius="0.111"/>
      </geometry>
    </collision>
  </link>
  <gazebo reference="p3at_front_right_wheel">
    <material value="Gazebo/Black"/>
  </gazebo>
  <joint name="p3at_front_right_wheel_joint" type="continuous">
    <axis xyz="0 1 0"/>
    <anchor xyz="0 0 0"/>
    <limit effort="100" velocity="100"/>
    <joint_properties damping="0.7"/>
    <origin rpy="0 0 0" xyz="0 0 0"/>
    <parent link="p3at_front_right_hub"/>
    <child link="p3at_front_right_wheel"/>
  </joint>
  <!-- Back Axles + Wheels + Hubcaps -->
  <link name="p3at_back_right_axle">
    <inertial>
      <mass value="0.1"/>
      <origin xyz="0 0 0"/>
      <inertia ixx="1.0" ixy="0.0" ixz="0.0" iyy="1.0" iyz="0.0" izz="1.0"/>
    </inertial>
    <visual>
      <origin rpy="0 0 0" xyz="0 0 0"/>
      <geometry name="pioneer_geom">
        <mesh filename="package://amr_robots_description/meshes/p3at_meshes/axle.stl"/>
      </geometry>
      <material name="AxleGrey">
        <color rgba="0.5 0.5 0.5 1"/>
      </material>
    </visual>
    <collision>
      <origin rpy="0 0 0" xyz="0 0 0"/>
      <geometry>
        <mesh filename="package://amr_robots_description/meshes/p3at_meshes/axle.stl"/>
      </geometry>
    </collision>
  </link>
  <gazebo reference="p3at_back_right_axle">
    <material value="Gazebo/Grey"/>
  </gazebo>
  <joint name="p3at_back_right_axle_joint" type="fixed">
    <origin rpy="0 0 0" xyz="-0.134 -0.156 0.111"/>
    <parent link="base_link"/>
    <child link="p3at_back_right_axle"/>
  </joint>
  <link name="p3at_back_right_hub">
    <inertial>
      <mass value="0.1"/>
      <origin xyz="0 0 0"/>
      <inertia ixx="1.0" ixy="0.0" ixz="0.0" iyy="1.0" iyz="0.0" izz="1.0"/>
    </inertial>
    <visual>
      <origin rpy="0 0 0" xyz="0 0 0"/>
      <geometry name="pioneer_geom">
        <mesh filename="package://amr_robots_description/meshes/p3at_meshes/right_hubcap.stl"/>
      </geometry>
      <material name="HubcapYellow"/>
    </visual>
    <collision>
      <origin rpy="0 0 0" xyz="0 0 0"/>
      <geometry>
        <mesh filename="package://amr_robots_description/meshes/p3at_meshes/right_hubcap.stl"/>
      </geometry>
    </collision>
  </link>
  <gazebo reference="p3at_back_right_hub">
    <material value="Gazebo/Yellow"/>
  </gazebo>
  <joint name="p3at_back_right_hub_joint" type="fixed">
    <origin rpy="0 0 0" xyz="-0 -0.041 0"/>
    <parent link="p3at_back_right_axle"/>
    <child link="p3at_back_right_hub"/>
  </joint>
  <link name="p3at_back_right_wheel">
    <inertial>
      <mass value="1.2"/>
      <origin xyz="0 0 0"/>
      <inertia ixx="0.012411765597" ixy="0" ixz="0" iyy="0.015218160428" iyz="0" izz="0.011763977943"/>
    </inertial>
    <visual>
      <origin rpy="0 0 0" xyz="0 0 0"/>
      <geometry name="pioneer_geom">
        <mesh filename="package://amr_robots_description/meshes/p3at_meshes/wheel.stl"/>
      </geometry>
      <material name="WheelBlack"/>
    </visual>
    <collision>
      <origin rpy="-1.57079635 0 0" xyz="0 0 0"/>
      <geometry>
        <!--mesh filename="package://amr_robots_description/meshes/p3at_meshes/wheel.stl"/-->
        <cylinder length="0.075" radius="0.111"/>
      </geometry>
    </collision>
  </link>
  <gazebo reference="p3at_back_right_wheel">
    <material value="Gazebo/Black"/>
  </gazebo>
  <joint name="p3at_back_right_wheel_joint" type="continuous">
    <axis xyz="0 1 0"/>
    <anchor xyz="0 0 0"/>
    <limit effort="100" velocity="100"/>
    <joint_properties damping="0.7"/>
    <origin rpy="0 0 0" xyz="0 0 0"/>
    <parent link="p3at_back_right_hub"/>
    <child link="p3at_back_right_wheel"/>
  </joint>
  <!-- see http://gazebosim.org/tutorials/?tut=ros_urdf -->
  <gazebo reference="p3at_back_right_wheel">
    <kp>1000000.0</kp>
    <!-- kp and kd for rubber -->
    <kd>100.0</kd>
    <mu1>1.0</mu1>
    <!-- was 10 -->
    <mu2>1.0</mu2>
    <!-- how to get these into <surface><friction><ode>... ?
        slip1 0.5 /slip1 
         slip2 0 /slip2 
      -->
    <!-- fdir1 0 1 0 /fdir1 -->
    <!-- see http://github.com/MobileRobots/amr-ros-config/issues/6 -->
    <maxVel>1.0</maxVel>
    <minDepth>0.00</minDepth>
    <material value="Gazebo/Black"/>
  </gazebo>
  <gazebo reference="p3at_front_right_wheel">
    <kp>1000000.0</kp>
    <!-- kp and kd for rubber -->
    <kd>100.0</kd>
    <mu1>1.0</mu1>
    <!-- was 10 -->
    <mu2>1.0</mu2>
    <!-- how to get these into <surface><friction><ode>... ?
        slip1 0.5 /slip1 
         slip2 0 /slip2 
      -->
    <!-- fdir1 0 1 0 /fdir1 -->
    <!-- see http://github.com/MobileRobots/amr-ros-config/issues/6 -->
    <maxVel>1.0</maxVel>
    <minDepth>0.00</minDepth>
    <material value="Gazebo/Black"/>
  </gazebo>

  <gazebo>
    <plugin name="differential_drive_controller" filename="libgazebo_ros_diff_drive.so">
      <leftJoint>p3at_back_left_wheel_joint</leftJoint>
      <rightJoint>p3at_back_right_wheel_joint</rightJoint>
      <robotBaseFrame>base_link</robotBaseFrame>
      <wheelSeparation>0.4</wheelSeparation>
      <wheelDiameter>0.215</wheelDiameter>
      <publishWheelJointState>true</publishWheelJointState>
    </plugin>
  </gazebo>

  <gazebo>
    <plugin name="differential_drive_controller" filename="libgazebo_ros_diff_drive.so">
      <leftJoint>p3at_front_left_wheel_joint</leftJoint>
      <rightJoint>p3at_front_right_wheel_joint</rightJoint>
      <robotBaseFrame>base_link</robotBaseFrame>
      <wheelSeparation>0.4</wheelSeparation>
      <wheelDiameter>0.215</wheelDiameter>
      <publishWheelJointState>true</publishWheelJointState>
    </plugin>
  </gazebo>

 <link name="camera_link">
    <visual>
      <origin xyz="0 0 0" rpy="0 0 0"/>
      <geometry>
        <box size="0.075 0.2 .075"/>
      </geometry>
    </visual>
    
  </link>

  <joint name="camera_joint" type="fixed">
    <axis xyz="0 1 0" />
    <origin xyz="0.1 0 0.3" rpy="0 0 0"/>
    <parent link="base_link"/>
    <child link="camera_link"/>
  </joint>

 <joint name="camera_depth_joint" type="fixed">
    <origin xyz="0 0 0" rpy="-1.57 0 -1.57 "/>
    <parent link="camera_link"/>
    <child link="camera_depth_link"/>
  </joint>

  <link name="camera_depth_link"></link>

<gazebo reference="camera_link">
  <sensor name="depth_camera" type="depth">
    <update_rate>20</update_rate>
    <camera>
      <horizontal_fov>1.047198</horizontal_fov>
      <image>
        <width>640</width>
        <height>480</height>
        <format>R8G8B8</format>
      </image>
      <clip>
        <near>0.05</near>
        <far>3</far>
      </clip>
    </camera>
    <plugin name="camera_link_controller" filename="libgazebo_ros_openni_kinect.so">
      <baseline>0.2</baseline>
      <alwaysOn>true</alwaysOn>
      <updateRate>1.0</updateRate>
      <cameraName>camera_ir</cameraName>
      <imageTopicName>/camera/color/image_raw</imageTopicName>
      <cameraInfoTopicName>/camera/color/camera_info</cameraInfoTopicName>
      <depthImageTopicName>/camera/depth/image_raw</depthImageTopicName>
      <depthImageInfoTopicName>/camera/depth/camera_info</depthImageInfoTopicName>
      <pointCloudTopicName>/camera/depth/points</pointCloudTopicName>
      <depthimagecamerainfotopicname>Camera/depth/camera_info</depthimagecamerainfotopicname>
      <frameName>camera_depth_link</frameName>
      <pointCloudCutoff>0.5</pointCloudCutoff>
      <pointCloudCutoffMax>3.0</pointCloudCutoffMax>
      <distortionK1>0.00000001</distortionK1>
      <distortionK2>0.00000001</distortionK2>
      <distortionK3>0.00000001</distortionK3>
      <distortionT1>0.00000001</distortionT1>
      <distortionT2>0.00000001</distortionT2>
      <CxPrime>0</CxPrime>
      <Cx>0</Cx>
      <Cy>0</Cy>
      <focalLength>0</focalLength>
      <hackBaseline>0</hackBaseline>
    </plugin>
  </sensor>
</gazebo>


 <gazebo>
    <plugin name="novatel_gps_sim" filename="libhector_gazebo_ros_gps.so">
      <alwaysOn>1</alwaysOn>
      <updateRate>10.0</updateRate>
      <bodyName>base_link</bodyName>
      <topicName>/gps/fix</topicName>
      <velocityTopicName>/gps/fix_velocity</velocityTopicName>
    </plugin>
  </gazebo>

  <gazebo reference="camera_link">
    <sensor type="ray" name="head_hokuyo_sensor">
    <pose>0 0 0 0 0 0</pose>
    <visualize>false</visualize>
    <update_rate>40</update_rate>
      <ray>
        <scan>
        <horizontal>
        <samples>720</samples>
        <resolution>1</resolution>
        <min_angle>-1.570796</min_angle>
        <max_angle>1.570796</max_angle>
        </horizontal>
      </scan>
      <range>
        <min>0</min>
        <max>30.0</max>
        <resolution>0.01</resolution>
      </range>
    </ray>
      <plugin name="gazebo_ros_head_hokuyo_controller" filename="libgazebo_ros_laser.so">
      <topicName>/scan</topicName>
      <frameName>camera_link</frameName>
    </plugin>
    </sensor>
  </gazebo>

    <gazebo reference="base_link">
    <gravity>true</gravity>
    <sensor name="imu_sensor" type="imu">
      <always_on>true</always_on>
      <update_rate>100</update_rate>
      <visualize>true</visualize>
      <topic>__default_topic__</topic>
      <plugin filename="libgazebo_ros_imu_sensor.so" name="imu_plugin">
        <topicName>imu</topicName>
        <bodyName>base_link</bodyName>
        <updateRateHZ>10.0</updateRateHZ>
        <gaussianNoise>0.0</gaussianNoise>
        <xyzOffset>0 0 0</xyzOffset>
        <rpyOffset>0 0 0</rpyOffset>
        <frameName>base_link</frameName>
        <initialOrientationAsReference>false</initialOrientationAsReference>
      </plugin>
      <pose>0 0 0 0 0 0</pose>
    </sensor>
  </gazebo>

</robot>

